{"@t":"2022-02-14T07:44:11.9046772Z","@mt":"Failed (will repeat).","@l":"Error","@x":"System.Data.SqlClient.SqlException (0x80131904): A network-related or instance-specific error occurred while establishing a connection to SQL Server. The server was not found or was not accessible. Verify that the instance name is correct and that SQL Server is configured to allow remote connections. (provider: Named Pipes Provider, error: 40 - Could not open a connection to SQL Server) ---> System.ComponentModel.Win32Exception (0x80004005): The network path was not found\r\n   at System.Data.SqlClient.SqlInternalConnectionTds..ctor(DbConnectionPoolIdentity identity, SqlConnectionString connectionOptions, SqlCredential credential, Object providerInfo, String newPassword, SecureString newSecurePassword, Boolean redirectedUserInstance, SqlConnectionString userConnectionOptions, SessionData reconnectSessionData, DbConnectionPool pool, String accessToken, Boolean applyTransientFaultHandling, SqlAuthenticationProviderManager sqlAuthProviderManager)\r\n   at System.Data.SqlClient.SqlConnectionFactory.CreateConnection(DbConnectionOptions options, DbConnectionPoolKey poolKey, Object poolGroupProviderInfo, DbConnectionPool pool, DbConnection owningConnection, DbConnectionOptions userOptions)\r\n   at System.Data.ProviderBase.DbConnectionFactory.CreatePooledConnection(DbConnectionPool pool, DbConnection owningObject, DbConnectionOptions options, DbConnectionPoolKey poolKey, DbConnectionOptions userOptions)\r\n   at System.Data.ProviderBase.DbConnectionPool.CreateObject(DbConnection owningObject, DbConnectionOptions userOptions, DbConnectionInternal oldConnection)\r\n   at System.Data.ProviderBase.DbConnectionPool.UserCreateRequest(DbConnection owningObject, DbConnectionOptions userOptions, DbConnectionInternal oldConnection)\r\n   at System.Data.ProviderBase.DbConnectionPool.TryGetConnection(DbConnection owningObject, UInt32 waitForMultipleObjectsTimeout, Boolean allowCreate, Boolean onlyOneCheckConnection, DbConnectionOptions userOptions, DbConnectionInternal& connection)\r\n   at System.Data.ProviderBase.DbConnectionPool.TryGetConnection(DbConnection owningObject, TaskCompletionSource`1 retry, DbConnectionOptions userOptions, DbConnectionInternal& connection)\r\n   at System.Data.ProviderBase.DbConnectionFactory.TryGetConnection(DbConnection owningConnection, TaskCompletionSource`1 retry, DbConnectionOptions userOptions, DbConnectionInternal oldConnection, DbConnectionInternal& connection)\r\n   at System.Data.ProviderBase.DbConnectionInternal.TryOpenConnectionInternal(DbConnection outerConnection, DbConnectionFactory connectionFactory, TaskCompletionSource`1 retry, DbConnectionOptions userOptions)\r\n   at System.Data.SqlClient.SqlConnection.TryOpenInner(TaskCompletionSource`1 retry)\r\n   at System.Data.SqlClient.SqlConnection.TryOpen(TaskCompletionSource`1 retry)\r\n   at System.Data.SqlClient.SqlConnection.Open()\r\n   at NPoco.Database.OpenSharedConnectionImp(Boolean isInternal)\r\n   at NPoco.Database.BeginTransaction(IsolationLevel isolationLevel)\r\n   at Umbraco.Core.Scoping.Scope.get_Database() in D:\\a\\1\\s\\src\\Umbraco.Core\\Scoping\\Scope.cs:line 330\r\n   at Umbraco.Core.Sync.DatabaseServerMessenger.Sync() in D:\\a\\1\\s\\src\\Umbraco.Core\\Sync\\DatabaseServerMessenger.cs:line 263\r\n   at Umbraco.Web.Compose.DatabaseServerRegistrarAndMessengerComponent.InstructionProcessTask.PerformRun() in D:\\a\\1\\s\\src\\Umbraco.Web\\Compose\\DatabaseServerRegistrarAndMessengerComponent.cs:line 163\r\nClientConnectionId:00000000-0000-0000-0000-000000000000\r\nError Number:53,State:0,Class:20","SourceContext":"Umbraco.Web.Compose.DatabaseServerRegistrarAndMessengerComponent+InstructionProcessTask","ProcessId":18916,"ProcessName":"iisexpress","ThreadId":101,"AppDomainId":2,"AppDomainAppId":"LMW3SVC2ROOT","MachineName":"AAR00118","Log4NetLevel":"ERROR"}
{"@t":"2022-02-14T07:44:31.9937420Z","@mt":"Failed (will repeat).","@l":"Error","@x":"System.Data.SqlClient.SqlException (0x80131904): A network-related or instance-specific error occurred while establishing a connection to SQL Server. The server was not found or was not accessible. Verify that the instance name is correct and that SQL Server is configured to allow remote connections. (provider: Named Pipes Provider, error: 40 - Could not open a connection to SQL Server) ---> System.ComponentModel.Win32Exception (0x80004005): The network path was not found\r\n   at System.Data.SqlClient.SqlInternalConnectionTds..ctor(DbConnectionPoolIdentity identity, SqlConnectionString connectionOptions, SqlCredential credential, Object providerInfo, String newPassword, SecureString newSecurePassword, Boolean redirectedUserInstance, SqlConnectionString userConnectionOptions, SessionData reconnectSessionData, DbConnectionPool pool, String accessToken, Boolean applyTransientFaultHandling, SqlAuthenticationProviderManager sqlAuthProviderManager)\r\n   at System.Data.SqlClient.SqlConnectionFactory.CreateConnection(DbConnectionOptions options, DbConnectionPoolKey poolKey, Object poolGroupProviderInfo, DbConnectionPool pool, DbConnection owningConnection, DbConnectionOptions userOptions)\r\n   at System.Data.ProviderBase.DbConnectionFactory.CreatePooledConnection(DbConnectionPool pool, DbConnection owningObject, DbConnectionOptions options, DbConnectionPoolKey poolKey, DbConnectionOptions userOptions)\r\n   at System.Data.ProviderBase.DbConnectionPool.CreateObject(DbConnection owningObject, DbConnectionOptions userOptions, DbConnectionInternal oldConnection)\r\n   at System.Data.ProviderBase.DbConnectionPool.UserCreateRequest(DbConnection owningObject, DbConnectionOptions userOptions, DbConnectionInternal oldConnection)\r\n   at System.Data.ProviderBase.DbConnectionPool.TryGetConnection(DbConnection owningObject, UInt32 waitForMultipleObjectsTimeout, Boolean allowCreate, Boolean onlyOneCheckConnection, DbConnectionOptions userOptions, DbConnectionInternal& connection)\r\n   at System.Data.ProviderBase.DbConnectionPool.TryGetConnection(DbConnection owningObject, TaskCompletionSource`1 retry, DbConnectionOptions userOptions, DbConnectionInternal& connection)\r\n   at System.Data.ProviderBase.DbConnectionFactory.TryGetConnection(DbConnection owningConnection, TaskCompletionSource`1 retry, DbConnectionOptions userOptions, DbConnectionInternal oldConnection, DbConnectionInternal& connection)\r\n   at System.Data.ProviderBase.DbConnectionInternal.TryOpenConnectionInternal(DbConnection outerConnection, DbConnectionFactory connectionFactory, TaskCompletionSource`1 retry, DbConnectionOptions userOptions)\r\n   at System.Data.SqlClient.SqlConnection.TryOpenInner(TaskCompletionSource`1 retry)\r\n   at System.Data.SqlClient.SqlConnection.TryOpen(TaskCompletionSource`1 retry)\r\n   at System.Data.SqlClient.SqlConnection.Open()\r\n   at NPoco.Database.OpenSharedConnectionImp(Boolean isInternal)\r\n   at NPoco.Database.BeginTransaction(IsolationLevel isolationLevel)\r\n   at Umbraco.Core.Scoping.Scope.get_Database() in D:\\a\\1\\s\\src\\Umbraco.Core\\Scoping\\Scope.cs:line 330\r\n   at Umbraco.Core.Sync.DatabaseServerMessenger.Sync() in D:\\a\\1\\s\\src\\Umbraco.Core\\Sync\\DatabaseServerMessenger.cs:line 263\r\n   at Umbraco.Web.Compose.DatabaseServerRegistrarAndMessengerComponent.InstructionProcessTask.PerformRun() in D:\\a\\1\\s\\src\\Umbraco.Web\\Compose\\DatabaseServerRegistrarAndMessengerComponent.cs:line 163\r\nClientConnectionId:00000000-0000-0000-0000-000000000000\r\nError Number:53,State:0,Class:20","SourceContext":"Umbraco.Web.Compose.DatabaseServerRegistrarAndMessengerComponent+InstructionProcessTask","ProcessId":18916,"ProcessName":"iisexpress","ThreadId":90,"AppDomainId":2,"AppDomainAppId":"LMW3SVC2ROOT","MachineName":"AAR00118","Log4NetLevel":"ERROR"}
{"@t":"2022-02-14T07:44:37.0111886Z","@mt":"Failed (will repeat).","@l":"Error","@x":"System.Data.SqlClient.SqlException (0x80131904): A network-related or instance-specific error occurred while establishing a connection to SQL Server. The server was not found or was not accessible. Verify that the instance name is correct and that SQL Server is configured to allow remote connections. (provider: Named Pipes Provider, error: 40 - Could not open a connection to SQL Server) ---> System.ComponentModel.Win32Exception (0x80004005): The network path was not found\r\n   at System.Data.ProviderBase.DbConnectionPool.TryGetConnection(DbConnection owningObject, UInt32 waitForMultipleObjectsTimeout, Boolean allowCreate, Boolean onlyOneCheckConnection, DbConnectionOptions userOptions, DbConnectionInternal& connection)\r\n   at System.Data.ProviderBase.DbConnectionPool.TryGetConnection(DbConnection owningObject, TaskCompletionSource`1 retry, DbConnectionOptions userOptions, DbConnectionInternal& connection)\r\n   at System.Data.ProviderBase.DbConnectionFactory.TryGetConnection(DbConnection owningConnection, TaskCompletionSource`1 retry, DbConnectionOptions userOptions, DbConnectionInternal oldConnection, DbConnectionInternal& connection)\r\n   at System.Data.ProviderBase.DbConnectionInternal.TryOpenConnectionInternal(DbConnection outerConnection, DbConnectionFactory connectionFactory, TaskCompletionSource`1 retry, DbConnectionOptions userOptions)\r\n   at System.Data.SqlClient.SqlConnection.TryOpenInner(TaskCompletionSource`1 retry)\r\n   at System.Data.SqlClient.SqlConnection.TryOpen(TaskCompletionSource`1 retry)\r\n   at System.Data.SqlClient.SqlConnection.Open()\r\n   at NPoco.Database.OpenSharedConnectionImp(Boolean isInternal)\r\n   at NPoco.Database.BeginTransaction(IsolationLevel isolationLevel)\r\n   at Umbraco.Core.Scoping.Scope.get_Database() in D:\\a\\1\\s\\src\\Umbraco.Core\\Scoping\\Scope.cs:line 330\r\n   at Umbraco.Core.Sync.DatabaseServerMessenger.Sync() in D:\\a\\1\\s\\src\\Umbraco.Core\\Sync\\DatabaseServerMessenger.cs:line 263\r\n   at Umbraco.Web.Compose.DatabaseServerRegistrarAndMessengerComponent.InstructionProcessTask.PerformRun() in D:\\a\\1\\s\\src\\Umbraco.Web\\Compose\\DatabaseServerRegistrarAndMessengerComponent.cs:line 163\r\nClientConnectionId:00000000-0000-0000-0000-000000000000\r\nError Number:53,State:0,Class:20","SourceContext":"Umbraco.Web.Compose.DatabaseServerRegistrarAndMessengerComponent+InstructionProcessTask","ProcessId":18916,"ProcessName":"iisexpress","ThreadId":98,"AppDomainId":2,"AppDomainAppId":"LMW3SVC2ROOT","MachineName":"AAR00118","Log4NetLevel":"ERROR"}
{"@t":"2022-02-14T07:44:56.8269321Z","@mt":"Failed (will repeat).","@l":"Error","@x":"System.Data.SqlClient.SqlException (0x80131904): A network-related or instance-specific error occurred while establishing a connection to SQL Server. The server was not found or was not accessible. Verify that the instance name is correct and that SQL Server is configured to allow remote connections. (provider: Named Pipes Provider, error: 40 - Could not open a connection to SQL Server) ---> System.ComponentModel.Win32Exception (0x80004005): The network path was not found\r\n   at System.Data.SqlClient.SqlInternalConnectionTds..ctor(DbConnectionPoolIdentity identity, SqlConnectionString connectionOptions, SqlCredential credential, Object providerInfo, String newPassword, SecureString newSecurePassword, Boolean redirectedUserInstance, SqlConnectionString userConnectionOptions, SessionData reconnectSessionData, DbConnectionPool pool, String accessToken, Boolean applyTransientFaultHandling, SqlAuthenticationProviderManager sqlAuthProviderManager)\r\n   at System.Data.SqlClient.SqlConnectionFactory.CreateConnection(DbConnectionOptions options, DbConnectionPoolKey poolKey, Object poolGroupProviderInfo, DbConnectionPool pool, DbConnection owningConnection, DbConnectionOptions userOptions)\r\n   at System.Data.ProviderBase.DbConnectionFactory.CreatePooledConnection(DbConnectionPool pool, DbConnection owningObject, DbConnectionOptions options, DbConnectionPoolKey poolKey, DbConnectionOptions userOptions)\r\n   at System.Data.ProviderBase.DbConnectionPool.CreateObject(DbConnection owningObject, DbConnectionOptions userOptions, DbConnectionInternal oldConnection)\r\n   at System.Data.ProviderBase.DbConnectionPool.UserCreateRequest(DbConnection owningObject, DbConnectionOptions userOptions, DbConnectionInternal oldConnection)\r\n   at System.Data.ProviderBase.DbConnectionPool.TryGetConnection(DbConnection owningObject, UInt32 waitForMultipleObjectsTimeout, Boolean allowCreate, Boolean onlyOneCheckConnection, DbConnectionOptions userOptions, DbConnectionInternal& connection)\r\n   at System.Data.ProviderBase.DbConnectionPool.TryGetConnection(DbConnection owningObject, TaskCompletionSource`1 retry, DbConnectionOptions userOptions, DbConnectionInternal& connection)\r\n   at System.Data.ProviderBase.DbConnectionFactory.TryGetConnection(DbConnection owningConnection, TaskCompletionSource`1 retry, DbConnectionOptions userOptions, DbConnectionInternal oldConnection, DbConnectionInternal& connection)\r\n   at System.Data.ProviderBase.DbConnectionInternal.TryOpenConnectionInternal(DbConnection outerConnection, DbConnectionFactory connectionFactory, TaskCompletionSource`1 retry, DbConnectionOptions userOptions)\r\n   at System.Data.SqlClient.SqlConnection.TryOpenInner(TaskCompletionSource`1 retry)\r\n   at System.Data.SqlClient.SqlConnection.TryOpen(TaskCompletionSource`1 retry)\r\n   at System.Data.SqlClient.SqlConnection.Open()\r\n   at NPoco.Database.OpenSharedConnectionImp(Boolean isInternal)\r\n   at NPoco.Database.BeginTransaction(IsolationLevel isolationLevel)\r\n   at Umbraco.Core.Scoping.Scope.get_Database() in D:\\a\\1\\s\\src\\Umbraco.Core\\Scoping\\Scope.cs:line 330\r\n   at Umbraco.Core.Sync.DatabaseServerMessenger.Sync() in D:\\a\\1\\s\\src\\Umbraco.Core\\Sync\\DatabaseServerMessenger.cs:line 263\r\n   at Umbraco.Web.Compose.DatabaseServerRegistrarAndMessengerComponent.InstructionProcessTask.PerformRun() in D:\\a\\1\\s\\src\\Umbraco.Web\\Compose\\DatabaseServerRegistrarAndMessengerComponent.cs:line 163\r\nClientConnectionId:00000000-0000-0000-0000-000000000000\r\nError Number:53,State:0,Class:20","SourceContext":"Umbraco.Web.Compose.DatabaseServerRegistrarAndMessengerComponent+InstructionProcessTask","ProcessId":18916,"ProcessName":"iisexpress","ThreadId":96,"AppDomainId":2,"AppDomainAppId":"LMW3SVC2ROOT","MachineName":"AAR00118","Log4NetLevel":"ERROR"}
{"@t":"2022-02-14T07:44:57.5529794Z","@mt":"Failed.","@l":"Error","@x":"System.Data.SqlClient.SqlException (0x80131904): A network-related or instance-specific error occurred while establishing a connection to SQL Server. The server was not found or was not accessible. Verify that the instance name is correct and that SQL Server is configured to allow remote connections. (provider: Named Pipes Provider, error: 40 - Could not open a connection to SQL Server) ---> System.ComponentModel.Win32Exception (0x80004005): The network path was not found\r\n   at System.Data.ProviderBase.DbConnectionPool.TryGetConnection(DbConnection owningObject, UInt32 waitForMultipleObjectsTimeout, Boolean allowCreate, Boolean onlyOneCheckConnection, DbConnectionOptions userOptions, DbConnectionInternal& connection)\r\n   at System.Data.ProviderBase.DbConnectionPool.TryGetConnection(DbConnection owningObject, TaskCompletionSource`1 retry, DbConnectionOptions userOptions, DbConnectionInternal& connection)\r\n   at System.Data.ProviderBase.DbConnectionFactory.TryGetConnection(DbConnection owningConnection, TaskCompletionSource`1 retry, DbConnectionOptions userOptions, DbConnectionInternal oldConnection, DbConnectionInternal& connection)\r\n   at System.Data.ProviderBase.DbConnectionInternal.TryOpenConnectionInternal(DbConnection outerConnection, DbConnectionFactory connectionFactory, TaskCompletionSource`1 retry, DbConnectionOptions userOptions)\r\n   at System.Data.SqlClient.SqlConnection.TryOpenInner(TaskCompletionSource`1 retry)\r\n   at System.Data.SqlClient.SqlConnection.TryOpen(TaskCompletionSource`1 retry)\r\n   at System.Data.SqlClient.SqlConnection.Open()\r\n   at NPoco.Database.OpenSharedConnectionImp(Boolean isInternal)\r\n   at NPoco.Database.BeginTransaction(IsolationLevel isolationLevel)\r\n   at Umbraco.Core.Scoping.Scope.get_Database() in D:\\a\\1\\s\\src\\Umbraco.Core\\Scoping\\Scope.cs:line 330\r\n   at Umbraco.Core.Persistence.Repositories.Implement.DocumentRepository.HasContentForRelease(DateTime date) in D:\\a\\1\\s\\src\\Umbraco.Core\\Persistence\\Repositories\\Implement\\DocumentRepository.cs:line 1050\r\n   at Umbraco.Core.Services.Implement.ContentService.PerformScheduledPublishingRelease(DateTime date, List`1 results, EventMessages evtMsgs, Lazy`1 allLangs) in D:\\a\\1\\s\\src\\Umbraco.Core\\Services\\Implement\\ContentService.cs:line 1467\r\n   at Umbraco.Core.Services.Implement.ContentService.PerformScheduledPublish(DateTime date) in D:\\a\\1\\s\\src\\Umbraco.Core\\Services\\Implement\\ContentService.cs:line 1396\r\n   at Umbraco.Web.Scheduling.ScheduledPublishing.PerformRun() in D:\\a\\1\\s\\src\\Umbraco.Web\\Scheduling\\ScheduledPublishing.cs:line 68\r\nClientConnectionId:00000000-0000-0000-0000-000000000000\r\nError Number:53,State:0,Class:20","SourceContext":"Umbraco.Web.Scheduling.ScheduledPublishing","ProcessId":18916,"ProcessName":"iisexpress","ThreadId":92,"AppDomainId":2,"AppDomainAppId":"LMW3SVC2ROOT","MachineName":"AAR00118","Log4NetLevel":"ERROR"}
{"@t":"2022-02-14T07:45:01.8390874Z","@mt":"Failed (will repeat).","@l":"Error","@x":"System.Data.SqlClient.SqlException (0x80131904): A network-related or instance-specific error occurred while establishing a connection to SQL Server. The server was not found or was not accessible. Verify that the instance name is correct and that SQL Server is configured to allow remote connections. (provider: Named Pipes Provider, error: 40 - Could not open a connection to SQL Server) ---> System.ComponentModel.Win32Exception (0x80004005): The network path was not found\r\n   at System.Data.ProviderBase.DbConnectionPool.TryGetConnection(DbConnection owningObject, UInt32 waitForMultipleObjectsTimeout, Boolean allowCreate, Boolean onlyOneCheckConnection, DbConnectionOptions userOptions, DbConnectionInternal& connection)\r\n   at System.Data.ProviderBase.DbConnectionPool.TryGetConnection(DbConnection owningObject, TaskCompletionSource`1 retry, DbConnectionOptions userOptions, DbConnectionInternal& connection)\r\n   at System.Data.ProviderBase.DbConnectionFactory.TryGetConnection(DbConnection owningConnection, TaskCompletionSource`1 retry, DbConnectionOptions userOptions, DbConnectionInternal oldConnection, DbConnectionInternal& connection)\r\n   at System.Data.ProviderBase.DbConnectionInternal.TryOpenConnectionInternal(DbConnection outerConnection, DbConnectionFactory connectionFactory, TaskCompletionSource`1 retry, DbConnectionOptions userOptions)\r\n   at System.Data.SqlClient.SqlConnection.TryOpenInner(TaskCompletionSource`1 retry)\r\n   at System.Data.SqlClient.SqlConnection.TryOpen(TaskCompletionSource`1 retry)\r\n   at System.Data.SqlClient.SqlConnection.Open()\r\n   at NPoco.Database.OpenSharedConnectionImp(Boolean isInternal)\r\n   at NPoco.Database.BeginTransaction(IsolationLevel isolationLevel)\r\n   at Umbraco.Core.Scoping.Scope.get_Database() in D:\\a\\1\\s\\src\\Umbraco.Core\\Scoping\\Scope.cs:line 330\r\n   at Umbraco.Core.Sync.DatabaseServerMessenger.Sync() in D:\\a\\1\\s\\src\\Umbraco.Core\\Sync\\DatabaseServerMessenger.cs:line 263\r\n   at Umbraco.Web.Compose.DatabaseServerRegistrarAndMessengerComponent.InstructionProcessTask.PerformRun() in D:\\a\\1\\s\\src\\Umbraco.Web\\Compose\\DatabaseServerRegistrarAndMessengerComponent.cs:line 163\r\nClientConnectionId:00000000-0000-0000-0000-000000000000\r\nError Number:53,State:0,Class:20","SourceContext":"Umbraco.Web.Compose.DatabaseServerRegistrarAndMessengerComponent+InstructionProcessTask","ProcessId":18916,"ProcessName":"iisexpress","ThreadId":96,"AppDomainId":2,"AppDomainAppId":"LMW3SVC2ROOT","MachineName":"AAR00118","Log4NetLevel":"ERROR"}
{"@t":"2022-02-14T07:45:06.8804692Z","@mt":"Failed (will repeat).","@l":"Error","@x":"System.Data.SqlClient.SqlException (0x80131904): A network-related or instance-specific error occurred while establishing a connection to SQL Server. The server was not found or was not accessible. Verify that the instance name is correct and that SQL Server is configured to allow remote connections. (provider: Named Pipes Provider, error: 40 - Could not open a connection to SQL Server) ---> System.ComponentModel.Win32Exception (0x80004005): The network path was not found\r\n   at System.Data.ProviderBase.DbConnectionPool.TryGetConnection(DbConnection owningObject, UInt32 waitForMultipleObjectsTimeout, Boolean allowCreate, Boolean onlyOneCheckConnection, DbConnectionOptions userOptions, DbConnectionInternal& connection)\r\n   at System.Data.ProviderBase.DbConnectionPool.TryGetConnection(DbConnection owningObject, TaskCompletionSource`1 retry, DbConnectionOptions userOptions, DbConnectionInternal& connection)\r\n   at System.Data.ProviderBase.DbConnectionFactory.TryGetConnection(DbConnection owningConnection, TaskCompletionSource`1 retry, DbConnectionOptions userOptions, DbConnectionInternal oldConnection, DbConnectionInternal& connection)\r\n   at System.Data.ProviderBase.DbConnectionInternal.TryOpenConnectionInternal(DbConnection outerConnection, DbConnectionFactory connectionFactory, TaskCompletionSource`1 retry, DbConnectionOptions userOptions)\r\n   at System.Data.SqlClient.SqlConnection.TryOpenInner(TaskCompletionSource`1 retry)\r\n   at System.Data.SqlClient.SqlConnection.TryOpen(TaskCompletionSource`1 retry)\r\n   at System.Data.SqlClient.SqlConnection.Open()\r\n   at NPoco.Database.OpenSharedConnectionImp(Boolean isInternal)\r\n   at NPoco.Database.BeginTransaction(IsolationLevel isolationLevel)\r\n   at Umbraco.Core.Scoping.Scope.get_Database() in D:\\a\\1\\s\\src\\Umbraco.Core\\Scoping\\Scope.cs:line 330\r\n   at Umbraco.Core.Sync.DatabaseServerMessenger.Sync() in D:\\a\\1\\s\\src\\Umbraco.Core\\Sync\\DatabaseServerMessenger.cs:line 263\r\n   at Umbraco.Web.Compose.DatabaseServerRegistrarAndMessengerComponent.InstructionProcessTask.PerformRun() in D:\\a\\1\\s\\src\\Umbraco.Web\\Compose\\DatabaseServerRegistrarAndMessengerComponent.cs:line 163\r\nClientConnectionId:00000000-0000-0000-0000-000000000000\r\nError Number:53,State:0,Class:20","SourceContext":"Umbraco.Web.Compose.DatabaseServerRegistrarAndMessengerComponent+InstructionProcessTask","ProcessId":18916,"ProcessName":"iisexpress","ThreadId":64,"AppDomainId":2,"AppDomainAppId":"LMW3SVC2ROOT","MachineName":"AAR00118","Log4NetLevel":"ERROR"}
{"@t":"2022-02-14T07:45:11.8961060Z","@mt":"Failed (will repeat).","@l":"Error","@x":"System.Data.SqlClient.SqlException (0x80131904): A network-related or instance-specific error occurred while establishing a connection to SQL Server. The server was not found or was not accessible. Verify that the instance name is correct and that SQL Server is configured to allow remote connections. (provider: Named Pipes Provider, error: 40 - Could not open a connection to SQL Server) ---> System.ComponentModel.Win32Exception (0x80004005): The network path was not found\r\n   at System.Data.ProviderBase.DbConnectionPool.TryGetConnection(DbConnection owningObject, UInt32 waitForMultipleObjectsTimeout, Boolean allowCreate, Boolean onlyOneCheckConnection, DbConnectionOptions userOptions, DbConnectionInternal& connection)\r\n   at System.Data.ProviderBase.DbConnectionPool.TryGetConnection(DbConnection owningObject, TaskCompletionSource`1 retry, DbConnectionOptions userOptions, DbConnectionInternal& connection)\r\n   at System.Data.ProviderBase.DbConnectionFactory.TryGetConnection(DbConnection owningConnection, TaskCompletionSource`1 retry, DbConnectionOptions userOptions, DbConnectionInternal oldConnection, DbConnectionInternal& connection)\r\n   at System.Data.ProviderBase.DbConnectionInternal.TryOpenConnectionInternal(DbConnection outerConnection, DbConnectionFactory connectionFactory, TaskCompletionSource`1 retry, DbConnectionOptions userOptions)\r\n   at System.Data.SqlClient.SqlConnection.TryOpenInner(TaskCompletionSource`1 retry)\r\n   at System.Data.SqlClient.SqlConnection.TryOpen(TaskCompletionSource`1 retry)\r\n   at System.Data.SqlClient.SqlConnection.Open()\r\n   at NPoco.Database.OpenSharedConnectionImp(Boolean isInternal)\r\n   at NPoco.Database.BeginTransaction(IsolationLevel isolationLevel)\r\n   at Umbraco.Core.Scoping.Scope.get_Database() in D:\\a\\1\\s\\src\\Umbraco.Core\\Scoping\\Scope.cs:line 330\r\n   at Umbraco.Core.Sync.DatabaseServerMessenger.Sync() in D:\\a\\1\\s\\src\\Umbraco.Core\\Sync\\DatabaseServerMessenger.cs:line 263\r\n   at Umbraco.Web.Compose.DatabaseServerRegistrarAndMessengerComponent.InstructionProcessTask.PerformRun() in D:\\a\\1\\s\\src\\Umbraco.Web\\Compose\\DatabaseServerRegistrarAndMessengerComponent.cs:line 163\r\nClientConnectionId:00000000-0000-0000-0000-000000000000\r\nError Number:53,State:0,Class:20","SourceContext":"Umbraco.Web.Compose.DatabaseServerRegistrarAndMessengerComponent+InstructionProcessTask","ProcessId":18916,"ProcessName":"iisexpress","ThreadId":89,"AppDomainId":2,"AppDomainAppId":"LMW3SVC2ROOT","MachineName":"AAR00118","Log4NetLevel":"ERROR"}
{"@t":"2022-02-14T07:51:28.4141717Z","@mt":"[{EventType}] Event Id: {EventId}, State: {State}","EventType":"Information","EventId":0,"State":"Login attempt succeeded for username oliver.gjesing@akqa.com from IP address ::1","SourceContext":"Umbraco.Core.Logging.OwinLogger","ProcessId":18916,"ProcessName":"iisexpress","ThreadId":99,"AppDomainId":2,"AppDomainAppId":"LMW3SVC2ROOT","MachineName":"AAR00118","Log4NetLevel":"INFO ","HttpRequestNumber":7,"HttpRequestId":"0ecc432e-2935-4895-80f4-d9d9ba3ba77f"}
{"@t":"2022-02-14T07:51:28.4141717Z","@mt":"[{EventType}] Event Id: {EventId}, State: {State}","EventType":"Information","EventId":0,"State":"User: oliver.gjesing@akqa.com logged in from IP address ::1","SourceContext":"Umbraco.Core.Logging.OwinLogger","ProcessId":18916,"ProcessName":"iisexpress","ThreadId":99,"AppDomainId":2,"AppDomainAppId":"LMW3SVC2ROOT","MachineName":"AAR00118","Log4NetLevel":"INFO ","HttpRequestNumber":7,"HttpRequestId":"0ecc432e-2935-4895-80f4-d9d9ba3ba77f"}
{"@t":"2022-02-14T07:51:40.7786321Z","@mt":"Exception","@l":"Error","@x":"ImageProcessor.Common.Exceptions.ImageProcessingException: ProcessImageAsync 609 : No image exists at D:\\Users\\Oliver.Gjesing.EMEA\\Documents\\Git\\FTO\\BE\\Flight2Orbit\\media\\bddkxw1w\\9368855062_a548b9c5eb_o.jpg","SourceContext":"ImageProcessor.Web.HttpModules.ImageProcessingModule","ProcessId":18916,"ProcessName":"iisexpress","ThreadId":110,"AppDomainId":2,"AppDomainAppId":"LMW3SVC2ROOT","MachineName":"AAR00118","Log4NetLevel":"ERROR","HttpRequestNumber":8,"HttpRequestId":"deacae7f-9bfc-4e4e-b9e5-ca73ab727f94"}
{"@t":"2022-02-14T07:59:00.2764644Z","@mt":"An error occurred during the index commit operation, if this error is persistent then index rebuilding is necessary","@l":"Error","@x":"System.IO.FileNotFoundException: Could not find file 'D:\\Users\\Oliver.Gjesing.EMEA\\Documents\\Git\\FTO\\BE\\Flight2Orbit\\App_Data\\TEMP\\ExamineIndexes\\Internal\\_bg.fnm'.\r\nFile name: 'D:\\Users\\Oliver.Gjesing.EMEA\\Documents\\Git\\FTO\\BE\\Flight2Orbit\\App_Data\\TEMP\\ExamineIndexes\\Internal\\_bg.fnm'\r\n   at System.IO.__Error.WinIOError(Int32 errorCode, String maybeFullPath)\r\n   at System.IO.FileStream.Init(String path, FileMode mode, FileAccess access, Int32 rights, Boolean useRights, FileShare share, Int32 bufferSize, FileOptions options, SECURITY_ATTRIBUTES secAttrs, String msgPath, Boolean bFromProxy, Boolean useLongPath, Boolean checkHost)\r\n   at System.IO.FileStream..ctor(String path, FileMode mode, FileAccess access, FileShare share)\r\n   at Lucene.Net.Store.SimpleFSDirectory.OpenInput(String name, Int32 bufferSize) in d:\\Lucene.Net\\FullRepo\\trunk\\src\\core\\Store\\SimpleFSDirectory.cs:line 72\r\n   at Lucene.Net.Index.FieldInfos..ctor(Directory d, String name) in d:\\Lucene.Net\\FullRepo\\trunk\\src\\core\\Index\\FieldInfos.cs:line 73\r\n   at Lucene.Net.Index.SegmentReader.CoreReaders..ctor(SegmentReader origInstance, Directory dir, SegmentInfo si, Int32 readBufferSize, Int32 termsIndexDivisor) in d:\\Lucene.Net\\FullRepo\\trunk\\src\\core\\Index\\SegmentReader.cs:line 125\r\n   at Lucene.Net.Index.SegmentReader.Get(Boolean readOnly, Directory dir, SegmentInfo si, Int32 readBufferSize, Boolean doOpenStores, Int32 termInfosIndexDivisor) in d:\\Lucene.Net\\FullRepo\\trunk\\src\\core\\Index\\SegmentReader.cs:line 779\r\n   at Lucene.Net.Index.IndexWriter.ReaderPool.Get(SegmentInfo info, Boolean doOpenStores, Int32 readBufferSize, Int32 termsIndexDivisor) in d:\\Lucene.Net\\FullRepo\\trunk\\src\\core\\Index\\IndexWriter.cs:line 689\r\n   at Lucene.Net.Index.IndexWriter.ReaderPool.Get(SegmentInfo info, Boolean doOpenStores) in d:\\Lucene.Net\\FullRepo\\trunk\\src\\core\\Index\\IndexWriter.cs:line 656\r\n   at Lucene.Net.Index.DocumentsWriter.ApplyDeletes(SegmentInfos infos) in d:\\Lucene.Net\\FullRepo\\trunk\\src\\core\\Index\\DocumentsWriter.cs:line 1265\r\n   at Lucene.Net.Index.IndexWriter.ApplyDeletes() in d:\\Lucene.Net\\FullRepo\\trunk\\src\\core\\Index\\IndexWriter.cs:line 5367\r\n   at Lucene.Net.Index.IndexWriter.DoFlushInternal(Boolean flushDocStores, Boolean flushDeletes) in d:\\Lucene.Net\\FullRepo\\trunk\\src\\core\\Index\\IndexWriter.cs:line 4377\r\n   at Lucene.Net.Index.IndexWriter.DoFlush(Boolean flushDocStores, Boolean flushDeletes) in d:\\Lucene.Net\\FullRepo\\trunk\\src\\core\\Index\\IndexWriter.cs:line 4197\r\n   at Lucene.Net.Index.IndexWriter.PrepareCommit(IDictionary`2 commitUserData) in d:\\Lucene.Net\\FullRepo\\trunk\\src\\core\\Index\\IndexWriter.cs:line 4034\r\n   at Lucene.Net.Index.IndexWriter.Commit(IDictionary`2 commitUserData) in d:\\Lucene.Net\\FullRepo\\trunk\\src\\core\\Index\\IndexWriter.cs:line 4116\r\n   at Examine.LuceneEngine.Providers.LuceneIndex.IndexCommiter.TimerRelease() in C:\\projects\\examine-qvx04\\src\\Examine\\LuceneEngine\\Providers\\LuceneIndex.cs:line 1097","SourceContext":"Umbraco.Examine.UmbracoContentIndex","ProcessId":18916,"ProcessName":"iisexpress","ThreadId":109,"AppDomainId":2,"AppDomainAppId":"LMW3SVC2ROOT","MachineName":"AAR00118","Log4NetLevel":"ERROR"}
{"@t":"2022-02-14T07:59:00.6568151Z","@mt":"Concurrent merge failed for index: ExternalIndex if this error is persistent then index rebuilding is necessary","@l":"Error","@x":"Lucene.Net.Index.MergePolicy+MergeException: Exception of type 'Lucene.Net.Index.MergePolicy+MergeException' was thrown. ---> Lucene.Net.Index.CorruptIndexException: doc counts differ for segment _da: fieldsReader shows 65 but segmentInfo shows 1\r\n   at Lucene.Net.Index.IndexWriter.HandleMergeException(Exception t, OneMerge merge) in d:\\Lucene.Net\\FullRepo\\trunk\\src\\core\\Index\\IndexWriter.cs:line 4641\r\n   at Lucene.Net.Index.IndexWriter.Merge(OneMerge merge) in d:\\Lucene.Net\\FullRepo\\trunk\\src\\core\\Index\\IndexWriter.cs:line 4674\r\n   at Lucene.Net.Index.ConcurrentMergeScheduler.MergeThread.Run() in d:\\Lucene.Net\\FullRepo\\trunk\\src\\core\\Index\\ConcurrentMergeScheduler.cs:line 370\r\n   --- End of inner exception stack trace ---\r\n   at Lucene.Net.Index.ConcurrentMergeScheduler.HandleMergeException(Exception exc) in d:\\Lucene.Net\\FullRepo\\trunk\\src\\core\\Index\\ConcurrentMergeScheduler.cs:line 430\r\n   at Examine.LuceneEngine.Providers.ErrorLoggingConcurrentMergeScheduler.HandleMergeException(Exception exc) in C:\\projects\\examine-qvx04\\src\\Examine\\LuceneEngine\\Providers\\ErrorLoggingConcurrentMergeScheduler.cs:line 26","SourceContext":"Umbraco.Examine.UmbracoContentIndex","ProcessId":18916,"ProcessName":"iisexpress","ThreadId":74,"AppDomainId":2,"AppDomainAppId":"LMW3SVC2ROOT","MachineName":"AAR00118","Log4NetLevel":"ERROR"}
{"@t":"2022-02-14T07:59:05.4461007Z","@mt":"An error occurred during the index commit operation, if this error is persistent then index rebuilding is necessary","@l":"Error","@x":"System.IO.FileNotFoundException: Could not find file 'D:\\Users\\Oliver.Gjesing.EMEA\\Documents\\Git\\FTO\\BE\\Flight2Orbit\\App_Data\\TEMP\\ExamineIndexes\\Internal\\_bg.fnm'.\r\nFile name: 'D:\\Users\\Oliver.Gjesing.EMEA\\Documents\\Git\\FTO\\BE\\Flight2Orbit\\App_Data\\TEMP\\ExamineIndexes\\Internal\\_bg.fnm'\r\n   at System.IO.__Error.WinIOError(Int32 errorCode, String maybeFullPath)\r\n   at System.IO.FileStream.Init(String path, FileMode mode, FileAccess access, Int32 rights, Boolean useRights, FileShare share, Int32 bufferSize, FileOptions options, SECURITY_ATTRIBUTES secAttrs, String msgPath, Boolean bFromProxy, Boolean useLongPath, Boolean checkHost)\r\n   at System.IO.FileStream..ctor(String path, FileMode mode, FileAccess access, FileShare share)\r\n   at Lucene.Net.Store.SimpleFSDirectory.OpenInput(String name, Int32 bufferSize) in d:\\Lucene.Net\\FullRepo\\trunk\\src\\core\\Store\\SimpleFSDirectory.cs:line 72\r\n   at Lucene.Net.Index.FieldInfos..ctor(Directory d, String name) in d:\\Lucene.Net\\FullRepo\\trunk\\src\\core\\Index\\FieldInfos.cs:line 73\r\n   at Lucene.Net.Index.SegmentReader.CoreReaders..ctor(SegmentReader origInstance, Directory dir, SegmentInfo si, Int32 readBufferSize, Int32 termsIndexDivisor) in d:\\Lucene.Net\\FullRepo\\trunk\\src\\core\\Index\\SegmentReader.cs:line 125\r\n   at Lucene.Net.Index.SegmentReader.Get(Boolean readOnly, Directory dir, SegmentInfo si, Int32 readBufferSize, Boolean doOpenStores, Int32 termInfosIndexDivisor) in d:\\Lucene.Net\\FullRepo\\trunk\\src\\core\\Index\\SegmentReader.cs:line 779\r\n   at Lucene.Net.Index.IndexWriter.ReaderPool.Get(SegmentInfo info, Boolean doOpenStores, Int32 readBufferSize, Int32 termsIndexDivisor) in d:\\Lucene.Net\\FullRepo\\trunk\\src\\core\\Index\\IndexWriter.cs:line 689\r\n   at Lucene.Net.Index.IndexWriter.ReaderPool.Get(SegmentInfo info, Boolean doOpenStores) in d:\\Lucene.Net\\FullRepo\\trunk\\src\\core\\Index\\IndexWriter.cs:line 656\r\n   at Lucene.Net.Index.DocumentsWriter.ApplyDeletes(SegmentInfos infos) in d:\\Lucene.Net\\FullRepo\\trunk\\src\\core\\Index\\DocumentsWriter.cs:line 1265\r\n   at Lucene.Net.Index.IndexWriter.ApplyDeletes() in d:\\Lucene.Net\\FullRepo\\trunk\\src\\core\\Index\\IndexWriter.cs:line 5367\r\n   at Lucene.Net.Index.IndexWriter.DoFlushInternal(Boolean flushDocStores, Boolean flushDeletes) in d:\\Lucene.Net\\FullRepo\\trunk\\src\\core\\Index\\IndexWriter.cs:line 4377\r\n   at Lucene.Net.Index.IndexWriter.DoFlush(Boolean flushDocStores, Boolean flushDeletes) in d:\\Lucene.Net\\FullRepo\\trunk\\src\\core\\Index\\IndexWriter.cs:line 4197\r\n   at Lucene.Net.Index.IndexWriter.PrepareCommit(IDictionary`2 commitUserData) in d:\\Lucene.Net\\FullRepo\\trunk\\src\\core\\Index\\IndexWriter.cs:line 4034\r\n   at Lucene.Net.Index.IndexWriter.Commit(IDictionary`2 commitUserData) in d:\\Lucene.Net\\FullRepo\\trunk\\src\\core\\Index\\IndexWriter.cs:line 4116\r\n   at Examine.LuceneEngine.Providers.LuceneIndex.IndexCommiter.TimerRelease() in C:\\projects\\examine-qvx04\\src\\Examine\\LuceneEngine\\Providers\\LuceneIndex.cs:line 1097","SourceContext":"Umbraco.Examine.UmbracoContentIndex","ProcessId":18916,"ProcessName":"iisexpress","ThreadId":112,"AppDomainId":2,"AppDomainAppId":"LMW3SVC2ROOT","MachineName":"AAR00118","Log4NetLevel":"ERROR"}
{"@t":"2022-02-14T07:59:05.7134151Z","@mt":"Concurrent merge failed for index: ExternalIndex if this error is persistent then index rebuilding is necessary","@l":"Error","@x":"Lucene.Net.Index.MergePolicy+MergeException: Exception of type 'Lucene.Net.Index.MergePolicy+MergeException' was thrown. ---> Lucene.Net.Index.CorruptIndexException: doc counts differ for segment _da: fieldsReader shows 65 but segmentInfo shows 1\r\n   at Lucene.Net.Index.IndexWriter.HandleMergeException(Exception t, OneMerge merge) in d:\\Lucene.Net\\FullRepo\\trunk\\src\\core\\Index\\IndexWriter.cs:line 4641\r\n   at Lucene.Net.Index.IndexWriter.Merge(OneMerge merge) in d:\\Lucene.Net\\FullRepo\\trunk\\src\\core\\Index\\IndexWriter.cs:line 4674\r\n   at Lucene.Net.Index.ConcurrentMergeScheduler.MergeThread.Run() in d:\\Lucene.Net\\FullRepo\\trunk\\src\\core\\Index\\ConcurrentMergeScheduler.cs:line 370\r\n   --- End of inner exception stack trace ---\r\n   at Lucene.Net.Index.ConcurrentMergeScheduler.HandleMergeException(Exception exc) in d:\\Lucene.Net\\FullRepo\\trunk\\src\\core\\Index\\ConcurrentMergeScheduler.cs:line 430\r\n   at Examine.LuceneEngine.Providers.ErrorLoggingConcurrentMergeScheduler.HandleMergeException(Exception exc) in C:\\projects\\examine-qvx04\\src\\Examine\\LuceneEngine\\Providers\\ErrorLoggingConcurrentMergeScheduler.cs:line 26","SourceContext":"Umbraco.Examine.UmbracoContentIndex","ProcessId":18916,"ProcessName":"iisexpress","ThreadId":70,"AppDomainId":2,"AppDomainAppId":"LMW3SVC2ROOT","MachineName":"AAR00118","Log4NetLevel":"ERROR"}
{"@t":"2022-02-14T07:59:06.0240050Z","@mt":"Concurrent merge failed for index: ExternalIndex if this error is persistent then index rebuilding is necessary","@l":"Error","@x":"Lucene.Net.Index.MergePolicy+MergeException: Exception of type 'Lucene.Net.Index.MergePolicy+MergeException' was thrown. ---> Lucene.Net.Index.CorruptIndexException: doc counts differ for segment _da: fieldsReader shows 65 but segmentInfo shows 1\r\n   at Lucene.Net.Index.IndexWriter.HandleMergeException(Exception t, OneMerge merge) in d:\\Lucene.Net\\FullRepo\\trunk\\src\\core\\Index\\IndexWriter.cs:line 4641\r\n   at Lucene.Net.Index.IndexWriter.Merge(OneMerge merge) in d:\\Lucene.Net\\FullRepo\\trunk\\src\\core\\Index\\IndexWriter.cs:line 4674\r\n   at Lucene.Net.Index.ConcurrentMergeScheduler.MergeThread.Run() in d:\\Lucene.Net\\FullRepo\\trunk\\src\\core\\Index\\ConcurrentMergeScheduler.cs:line 370\r\n   --- End of inner exception stack trace ---\r\n   at Lucene.Net.Index.ConcurrentMergeScheduler.HandleMergeException(Exception exc) in d:\\Lucene.Net\\FullRepo\\trunk\\src\\core\\Index\\ConcurrentMergeScheduler.cs:line 430\r\n   at Examine.LuceneEngine.Providers.ErrorLoggingConcurrentMergeScheduler.HandleMergeException(Exception exc) in C:\\projects\\examine-qvx04\\src\\Examine\\LuceneEngine\\Providers\\ErrorLoggingConcurrentMergeScheduler.cs:line 26","SourceContext":"Umbraco.Examine.UmbracoContentIndex","ProcessId":18916,"ProcessName":"iisexpress","ThreadId":67,"AppDomainId":2,"AppDomainAppId":"LMW3SVC2ROOT","MachineName":"AAR00118","Log4NetLevel":"ERROR"}
{"@t":"2022-02-14T08:07:51.4787604Z","@mt":"Exception","@l":"Error","@x":"ImageProcessor.Common.Exceptions.ImageProcessingException: ProcessImageAsync 609 : No image exists at D:\\Users\\Oliver.Gjesing.EMEA\\Documents\\Git\\FTO\\BE\\Flight2Orbit\\media\\bddkxw1w\\9368855062_a548b9c5eb_o.jpg","SourceContext":"ImageProcessor.Web.HttpModules.ImageProcessingModule","ProcessId":18916,"ProcessName":"iisexpress","ThreadId":95,"AppDomainId":2,"AppDomainAppId":"LMW3SVC2ROOT","MachineName":"AAR00118","Log4NetLevel":"ERROR","HttpRequestNumber":9,"HttpRequestId":"2b9201ac-e897-4813-9aeb-58fb948f2433"}
{"@t":"2022-02-14T08:10:16.4871146Z","@mt":"Exception","@l":"Error","@x":"ImageProcessor.Common.Exceptions.ImageProcessingException: ProcessImageAsync 609 : No image exists at D:\\Users\\Oliver.Gjesing.EMEA\\Documents\\Git\\FTO\\BE\\Flight2Orbit\\media\\bddkxw1w\\9368855062_a548b9c5eb_o.jpg","SourceContext":"ImageProcessor.Web.HttpModules.ImageProcessingModule","ProcessId":18916,"ProcessName":"iisexpress","ThreadId":92,"AppDomainId":2,"AppDomainAppId":"LMW3SVC2ROOT","MachineName":"AAR00118","Log4NetLevel":"ERROR","HttpRequestNumber":10,"HttpRequestId":"dd1cdedb-6bb5-4b86-b010-b3c310f31d1b"}
{"@t":"2022-02-14T08:41:19.6827424Z","@mt":"Exception ({InstanceId}).","@l":"Error","@x":"System.Data.SqlClient.SqlException (0x80131904): A transport-level error has occurred when receiving results from the server. (provider: TCP Provider, error: 0 - The network connection was aborted by the local system.) ---> System.ComponentModel.Win32Exception (0x80004005): The network connection was aborted by the local system\r\n   at System.Data.SqlClient.SqlConnection.OnError(SqlException exception, Boolean breakConnection, Action`1 wrapCloseInAction)\r\n   at System.Data.SqlClient.TdsParser.ThrowExceptionAndWarning(TdsParserStateObject stateObj, Boolean callerHasConnectionLock, Boolean asyncClose)\r\n   at System.Data.SqlClient.TdsParserStateObject.ReadSniError(TdsParserStateObject stateObj, UInt32 error)\r\n   at System.Data.SqlClient.TdsParserStateObject.ReadSniSyncOverAsync()\r\n   at System.Data.SqlClient.TdsParserStateObject.TryReadNetworkPacket()\r\n   at System.Data.SqlClient.TdsParserStateObject.TryPrepareBuffer()\r\n   at System.Data.SqlClient.TdsParserStateObject.TryReadByte(Byte& value)\r\n   at System.Data.SqlClient.TdsParser.TryRun(RunBehavior runBehavior, SqlCommand cmdHandler, SqlDataReader dataStream, BulkCopySimpleResultSet bulkCopyHandler, TdsParserStateObject stateObj, Boolean& dataReady)\r\n   at System.Data.SqlClient.SqlDataReader.TryConsumeMetaData()\r\n   at System.Data.SqlClient.SqlDataReader.get_MetaData()\r\n   at System.Data.SqlClient.SqlCommand.FinishExecuteReader(SqlDataReader ds, RunBehavior runBehavior, String resetOptionsString, Boolean isInternal, Boolean forDescribeParameterEncryption, Boolean shouldCacheForAlwaysEncrypted)\r\n   at System.Data.SqlClient.SqlCommand.RunExecuteReaderTds(CommandBehavior cmdBehavior, RunBehavior runBehavior, Boolean returnStream, Boolean async, Int32 timeout, Task& task, Boolean asyncWrite, Boolean inRetry, SqlDataReader ds, Boolean describeParameterEncryptionRequest)\r\n   at System.Data.SqlClient.SqlCommand.RunExecuteReader(CommandBehavior cmdBehavior, RunBehavior runBehavior, Boolean returnStream, String method, TaskCompletionSource`1 completion, Int32 timeout, Task& task, Boolean& usedCache, Boolean asyncWrite, Boolean inRetry)\r\n   at System.Data.SqlClient.SqlCommand.RunExecuteReader(CommandBehavior cmdBehavior, RunBehavior runBehavior, Boolean returnStream, String method)\r\n   at System.Data.SqlClient.SqlCommand.ExecuteScalar()\r\n   at Umbraco.Core.Persistence.FaultHandling.RetryPolicy.ExecuteAction[TResult](Func`1 func) in D:\\a\\1\\s\\src\\Umbraco.Core\\Persistence\\FaultHandling\\RetryPolicy.cs:line 172\r\n   at NPoco.Database.ExecuteScalarHelper(DbCommand cmd)\r\n   at NPoco.Database.ExecuteScalar[T](String sql, CommandType commandType, Object[] args)\r\n   at Umbraco.Core.Sync.DatabaseServerMessenger.PruneOldInstructions(IUmbracoDatabase database) in D:\\a\\1\\s\\src\\Umbraco.Core\\Sync\\DatabaseServerMessenger.cs:line 448\r\n   at Umbraco.Core.Sync.DatabaseServerMessenger.Sync() in D:\\a\\1\\s\\src\\Umbraco.Core\\Sync\\DatabaseServerMessenger.cs:line 282\r\n   at Umbraco.Web.Compose.DatabaseServerRegistrarAndMessengerComponent.InstructionProcessTask.PerformRun() in D:\\a\\1\\s\\src\\Umbraco.Web\\Compose\\DatabaseServerRegistrarAndMessengerComponent.cs:line 163\r\nClientConnectionId:51b2ca68-8b65-48c2-9f3a-28cc8c16230b\r\nError Number:1236,State:0,Class:20","InstanceId":"6bd4531e","SourceContext":"Umbraco.Core.Persistence.UmbracoDatabase","ProcessId":18916,"ProcessName":"iisexpress","ThreadId":67,"AppDomainId":2,"AppDomainAppId":"LMW3SVC2ROOT","MachineName":"AAR00118","Log4NetLevel":"ERROR"}
{"@t":"2022-02-14T08:41:34.4976706Z","@mt":"Failed.","@l":"Error","@x":"System.Data.SqlClient.SqlException (0x80131904): A network-related or instance-specific error occurred while establishing a connection to SQL Server. The server was not found or was not accessible. Verify that the instance name is correct and that SQL Server is configured to allow remote connections. (provider: Named Pipes Provider, error: 40 - Could not open a connection to SQL Server) ---> System.ComponentModel.Win32Exception (0x80004005): The network path was not found\r\n   at System.Data.ProviderBase.DbConnectionPool.TryGetConnection(DbConnection owningObject, UInt32 waitForMultipleObjectsTimeout, Boolean allowCreate, Boolean onlyOneCheckConnection, DbConnectionOptions userOptions, DbConnectionInternal& connection)\r\n   at System.Data.ProviderBase.DbConnectionPool.TryGetConnection(DbConnection owningObject, TaskCompletionSource`1 retry, DbConnectionOptions userOptions, DbConnectionInternal& connection)\r\n   at System.Data.ProviderBase.DbConnectionFactory.TryGetConnection(DbConnection owningConnection, TaskCompletionSource`1 retry, DbConnectionOptions userOptions, DbConnectionInternal oldConnection, DbConnectionInternal& connection)\r\n   at System.Data.ProviderBase.DbConnectionInternal.TryOpenConnectionInternal(DbConnection outerConnection, DbConnectionFactory connectionFactory, TaskCompletionSource`1 retry, DbConnectionOptions userOptions)\r\n   at System.Data.SqlClient.SqlConnection.TryOpenInner(TaskCompletionSource`1 retry)\r\n   at System.Data.SqlClient.SqlConnection.TryOpen(TaskCompletionSource`1 retry)\r\n   at System.Data.SqlClient.SqlConnection.Open()\r\n   at NPoco.Database.OpenSharedConnectionImp(Boolean isInternal)\r\n   at NPoco.Database.BeginTransaction(IsolationLevel isolationLevel)\r\n   at Umbraco.Core.Scoping.Scope.get_Database() in D:\\a\\1\\s\\src\\Umbraco.Core\\Scoping\\Scope.cs:line 330\r\n   at Umbraco.Core.Persistence.Repositories.Implement.DocumentRepository.HasContentForRelease(DateTime date) in D:\\a\\1\\s\\src\\Umbraco.Core\\Persistence\\Repositories\\Implement\\DocumentRepository.cs:line 1050\r\n   at Umbraco.Core.Services.Implement.ContentService.PerformScheduledPublishingRelease(DateTime date, List`1 results, EventMessages evtMsgs, Lazy`1 allLangs) in D:\\a\\1\\s\\src\\Umbraco.Core\\Services\\Implement\\ContentService.cs:line 1467\r\n   at Umbraco.Core.Services.Implement.ContentService.PerformScheduledPublish(DateTime date) in D:\\a\\1\\s\\src\\Umbraco.Core\\Services\\Implement\\ContentService.cs:line 1396\r\n   at Umbraco.Web.Scheduling.ScheduledPublishing.PerformRun() in D:\\a\\1\\s\\src\\Umbraco.Web\\Scheduling\\ScheduledPublishing.cs:line 68\r\nClientConnectionId:00000000-0000-0000-0000-000000000000\r\nError Number:53,State:0,Class:20","SourceContext":"Umbraco.Web.Scheduling.ScheduledPublishing","ProcessId":18916,"ProcessName":"iisexpress","ThreadId":72,"AppDomainId":2,"AppDomainAppId":"LMW3SVC2ROOT","MachineName":"AAR00118","Log4NetLevel":"ERROR"}
{"@t":"2022-02-14T08:41:34.4976706Z","@mt":"Failed (will repeat).","@l":"Error","@x":"System.Data.SqlClient.SqlException (0x80131904): A network-related or instance-specific error occurred while establishing a connection to SQL Server. The server was not found or was not accessible. Verify that the instance name is correct and that SQL Server is configured to allow remote connections. (provider: Named Pipes Provider, error: 40 - Could not open a connection to SQL Server) ---> System.ComponentModel.Win32Exception (0x80004005): The network path was not found\r\n   at System.Data.SqlClient.SqlInternalConnectionTds..ctor(DbConnectionPoolIdentity identity, SqlConnectionString connectionOptions, SqlCredential credential, Object providerInfo, String newPassword, SecureString newSecurePassword, Boolean redirectedUserInstance, SqlConnectionString userConnectionOptions, SessionData reconnectSessionData, DbConnectionPool pool, String accessToken, Boolean applyTransientFaultHandling, SqlAuthenticationProviderManager sqlAuthProviderManager)\r\n   at System.Data.SqlClient.SqlConnectionFactory.CreateConnection(DbConnectionOptions options, DbConnectionPoolKey poolKey, Object poolGroupProviderInfo, DbConnectionPool pool, DbConnection owningConnection, DbConnectionOptions userOptions)\r\n   at System.Data.ProviderBase.DbConnectionFactory.CreatePooledConnection(DbConnectionPool pool, DbConnection owningObject, DbConnectionOptions options, DbConnectionPoolKey poolKey, DbConnectionOptions userOptions)\r\n   at System.Data.ProviderBase.DbConnectionPool.CreateObject(DbConnection owningObject, DbConnectionOptions userOptions, DbConnectionInternal oldConnection)\r\n   at System.Data.ProviderBase.DbConnectionPool.UserCreateRequest(DbConnection owningObject, DbConnectionOptions userOptions, DbConnectionInternal oldConnection)\r\n   at System.Data.ProviderBase.DbConnectionPool.TryGetConnection(DbConnection owningObject, UInt32 waitForMultipleObjectsTimeout, Boolean allowCreate, Boolean onlyOneCheckConnection, DbConnectionOptions userOptions, DbConnectionInternal& connection)\r\n   at System.Data.ProviderBase.DbConnectionPool.TryGetConnection(DbConnection owningObject, TaskCompletionSource`1 retry, DbConnectionOptions userOptions, DbConnectionInternal& connection)\r\n   at System.Data.ProviderBase.DbConnectionFactory.TryGetConnection(DbConnection owningConnection, TaskCompletionSource`1 retry, DbConnectionOptions userOptions, DbConnectionInternal oldConnection, DbConnectionInternal& connection)\r\n   at System.Data.ProviderBase.DbConnectionInternal.TryOpenConnectionInternal(DbConnection outerConnection, DbConnectionFactory connectionFactory, TaskCompletionSource`1 retry, DbConnectionOptions userOptions)\r\n   at System.Data.SqlClient.SqlConnection.TryOpenInner(TaskCompletionSource`1 retry)\r\n   at System.Data.SqlClient.SqlConnection.TryOpen(TaskCompletionSource`1 retry)\r\n   at System.Data.SqlClient.SqlConnection.Open()\r\n   at Umbraco.Core.Persistence.FaultHandling.RetryPolicy.<>c__DisplayClass20_0.<ExecuteAction>b__0() in D:\\a\\1\\s\\src\\Umbraco.Core\\Persistence\\FaultHandling\\RetryPolicy.cs:line 125\r\n   at Umbraco.Core.Persistence.FaultHandling.RetryPolicy.ExecuteAction[TResult](Func`1 func) in D:\\a\\1\\s\\src\\Umbraco.Core\\Persistence\\FaultHandling\\RetryPolicy.cs:line 172\r\n   at NPoco.Database.AbortTransaction(Boolean fromComplete)\r\n   at Umbraco.Core.Scoping.Scope.DisposeLastScope() in D:\\a\\1\\s\\src\\Umbraco.Core\\Scoping\\Scope.cs:line 621\r\n   at Umbraco.Core.Scoping.Scope.Dispose() in D:\\a\\1\\s\\src\\Umbraco.Core\\Scoping\\Scope.cs:line 557\r\n   at Umbraco.Core.Sync.DatabaseServerMessenger.Sync() in D:\\a\\1\\s\\src\\Umbraco.Core\\Sync\\DatabaseServerMessenger.cs:line 283\r\n   at Umbraco.Web.Compose.DatabaseServerRegistrarAndMessengerComponent.InstructionProcessTask.PerformRun() in D:\\a\\1\\s\\src\\Umbraco.Web\\Compose\\DatabaseServerRegistrarAndMessengerComponent.cs:line 163\r\nClientConnectionId:00000000-0000-0000-0000-000000000000\r\nError Number:53,State:0,Class:20","SourceContext":"Umbraco.Web.Compose.DatabaseServerRegistrarAndMessengerComponent+InstructionProcessTask","ProcessId":18916,"ProcessName":"iisexpress","ThreadId":67,"AppDomainId":2,"AppDomainAppId":"LMW3SVC2ROOT","MachineName":"AAR00118","Log4NetLevel":"ERROR"}
