{"@t":"2022-02-14T07:44:11.9046772Z","@mt":"Failed (will repeat).","@l":"Error","@x":"System.Data.SqlClient.SqlException (0x80131904): A network-related or instance-specific error occurred while establishing a connection to SQL Server. The server was not found or was not accessible. Verify that the instance name is correct and that SQL Server is configured to allow remote connections. (provider: Named Pipes Provider, error: 40 - Could not open a connection to SQL Server) ---> System.ComponentModel.Win32Exception (0x80004005): The network path was not found\r\n   at System.Data.SqlClient.SqlInternalConnectionTds..ctor(DbConnectionPoolIdentity identity, SqlConnectionString connectionOptions, SqlCredential credential, Object providerInfo, String newPassword, SecureString newSecurePassword, Boolean redirectedUserInstance, SqlConnectionString userConnectionOptions, SessionData reconnectSessionData, DbConnectionPool pool, String accessToken, Boolean applyTransientFaultHandling, SqlAuthenticationProviderManager sqlAuthProviderManager)\r\n   at System.Data.SqlClient.SqlConnectionFactory.CreateConnection(DbConnectionOptions options, DbConnectionPoolKey poolKey, Object poolGroupProviderInfo, DbConnectionPool pool, DbConnection owningConnection, DbConnectionOptions userOptions)\r\n   at System.Data.ProviderBase.DbConnectionFactory.CreatePooledConnection(DbConnectionPool pool, DbConnection owningObject, DbConnectionOptions options, DbConnectionPoolKey poolKey, DbConnectionOptions userOptions)\r\n   at System.Data.ProviderBase.DbConnectionPool.CreateObject(DbConnection owningObject, DbConnectionOptions userOptions, DbConnectionInternal oldConnection)\r\n   at System.Data.ProviderBase.DbConnectionPool.UserCreateRequest(DbConnection owningObject, DbConnectionOptions userOptions, DbConnectionInternal oldConnection)\r\n   at System.Data.ProviderBase.DbConnectionPool.TryGetConnection(DbConnection owningObject, UInt32 waitForMultipleObjectsTimeout, Boolean allowCreate, Boolean onlyOneCheckConnection, DbConnectionOptions userOptions, DbConnectionInternal& connection)\r\n   at System.Data.ProviderBase.DbConnectionPool.TryGetConnection(DbConnection owningObject, TaskCompletionSource`1 retry, DbConnectionOptions userOptions, DbConnectionInternal& connection)\r\n   at System.Data.ProviderBase.DbConnectionFactory.TryGetConnection(DbConnection owningConnection, TaskCompletionSource`1 retry, DbConnectionOptions userOptions, DbConnectionInternal oldConnection, DbConnectionInternal& connection)\r\n   at System.Data.ProviderBase.DbConnectionInternal.TryOpenConnectionInternal(DbConnection outerConnection, DbConnectionFactory connectionFactory, TaskCompletionSource`1 retry, DbConnectionOptions userOptions)\r\n   at System.Data.SqlClient.SqlConnection.TryOpenInner(TaskCompletionSource`1 retry)\r\n   at System.Data.SqlClient.SqlConnection.TryOpen(TaskCompletionSource`1 retry)\r\n   at System.Data.SqlClient.SqlConnection.Open()\r\n   at NPoco.Database.OpenSharedConnectionImp(Boolean isInternal)\r\n   at NPoco.Database.BeginTransaction(IsolationLevel isolationLevel)\r\n   at Umbraco.Core.Scoping.Scope.get_Database() in D:\\a\\1\\s\\src\\Umbraco.Core\\Scoping\\Scope.cs:line 330\r\n   at Umbraco.Core.Sync.DatabaseServerMessenger.Sync() in D:\\a\\1\\s\\src\\Umbraco.Core\\Sync\\DatabaseServerMessenger.cs:line 263\r\n   at Umbraco.Web.Compose.DatabaseServerRegistrarAndMessengerComponent.InstructionProcessTask.PerformRun() in D:\\a\\1\\s\\src\\Umbraco.Web\\Compose\\DatabaseServerRegistrarAndMessengerComponent.cs:line 163\r\nClientConnectionId:00000000-0000-0000-0000-000000000000\r\nError Number:53,State:0,Class:20","SourceContext":"Umbraco.Web.Compose.DatabaseServerRegistrarAndMessengerComponent+InstructionProcessTask","ProcessId":18916,"ProcessName":"iisexpress","ThreadId":101,"AppDomainId":2,"AppDomainAppId":"LMW3SVC2ROOT","MachineName":"AAR00118","Log4NetLevel":"ERROR"}
{"@t":"2022-02-14T07:44:31.9937420Z","@mt":"Failed (will repeat).","@l":"Error","@x":"System.Data.SqlClient.SqlException (0x80131904): A network-related or instance-specific error occurred while establishing a connection to SQL Server. The server was not found or was not accessible. Verify that the instance name is correct and that SQL Server is configured to allow remote connections. (provider: Named Pipes Provider, error: 40 - Could not open a connection to SQL Server) ---> System.ComponentModel.Win32Exception (0x80004005): The network path was not found\r\n   at System.Data.SqlClient.SqlInternalConnectionTds..ctor(DbConnectionPoolIdentity identity, SqlConnectionString connectionOptions, SqlCredential credential, Object providerInfo, String newPassword, SecureString newSecurePassword, Boolean redirectedUserInstance, SqlConnectionString userConnectionOptions, SessionData reconnectSessionData, DbConnectionPool pool, String accessToken, Boolean applyTransientFaultHandling, SqlAuthenticationProviderManager sqlAuthProviderManager)\r\n   at System.Data.SqlClient.SqlConnectionFactory.CreateConnection(DbConnectionOptions options, DbConnectionPoolKey poolKey, Object poolGroupProviderInfo, DbConnectionPool pool, DbConnection owningConnection, DbConnectionOptions userOptions)\r\n   at System.Data.ProviderBase.DbConnectionFactory.CreatePooledConnection(DbConnectionPool pool, DbConnection owningObject, DbConnectionOptions options, DbConnectionPoolKey poolKey, DbConnectionOptions userOptions)\r\n   at System.Data.ProviderBase.DbConnectionPool.CreateObject(DbConnection owningObject, DbConnectionOptions userOptions, DbConnectionInternal oldConnection)\r\n   at System.Data.ProviderBase.DbConnectionPool.UserCreateRequest(DbConnection owningObject, DbConnectionOptions userOptions, DbConnectionInternal oldConnection)\r\n   at System.Data.ProviderBase.DbConnectionPool.TryGetConnection(DbConnection owningObject, UInt32 waitForMultipleObjectsTimeout, Boolean allowCreate, Boolean onlyOneCheckConnection, DbConnectionOptions userOptions, DbConnectionInternal& connection)\r\n   at System.Data.ProviderBase.DbConnectionPool.TryGetConnection(DbConnection owningObject, TaskCompletionSource`1 retry, DbConnectionOptions userOptions, DbConnectionInternal& connection)\r\n   at System.Data.ProviderBase.DbConnectionFactory.TryGetConnection(DbConnection owningConnection, TaskCompletionSource`1 retry, DbConnectionOptions userOptions, DbConnectionInternal oldConnection, DbConnectionInternal& connection)\r\n   at System.Data.ProviderBase.DbConnectionInternal.TryOpenConnectionInternal(DbConnection outerConnection, DbConnectionFactory connectionFactory, TaskCompletionSource`1 retry, DbConnectionOptions userOptions)\r\n   at System.Data.SqlClient.SqlConnection.TryOpenInner(TaskCompletionSource`1 retry)\r\n   at System.Data.SqlClient.SqlConnection.TryOpen(TaskCompletionSource`1 retry)\r\n   at System.Data.SqlClient.SqlConnection.Open()\r\n   at NPoco.Database.OpenSharedConnectionImp(Boolean isInternal)\r\n   at NPoco.Database.BeginTransaction(IsolationLevel isolationLevel)\r\n   at Umbraco.Core.Scoping.Scope.get_Database() in D:\\a\\1\\s\\src\\Umbraco.Core\\Scoping\\Scope.cs:line 330\r\n   at Umbraco.Core.Sync.DatabaseServerMessenger.Sync() in D:\\a\\1\\s\\src\\Umbraco.Core\\Sync\\DatabaseServerMessenger.cs:line 263\r\n   at Umbraco.Web.Compose.DatabaseServerRegistrarAndMessengerComponent.InstructionProcessTask.PerformRun() in D:\\a\\1\\s\\src\\Umbraco.Web\\Compose\\DatabaseServerRegistrarAndMessengerComponent.cs:line 163\r\nClientConnectionId:00000000-0000-0000-0000-000000000000\r\nError Number:53,State:0,Class:20","SourceContext":"Umbraco.Web.Compose.DatabaseServerRegistrarAndMessengerComponent+InstructionProcessTask","ProcessId":18916,"ProcessName":"iisexpress","ThreadId":90,"AppDomainId":2,"AppDomainAppId":"LMW3SVC2ROOT","MachineName":"AAR00118","Log4NetLevel":"ERROR"}
{"@t":"2022-02-14T07:44:37.0111886Z","@mt":"Failed (will repeat).","@l":"Error","@x":"System.Data.SqlClient.SqlException (0x80131904): A network-related or instance-specific error occurred while establishing a connection to SQL Server. The server was not found or was not accessible. Verify that the instance name is correct and that SQL Server is configured to allow remote connections. (provider: Named Pipes Provider, error: 40 - Could not open a connection to SQL Server) ---> System.ComponentModel.Win32Exception (0x80004005): The network path was not found\r\n   at System.Data.ProviderBase.DbConnectionPool.TryGetConnection(DbConnection owningObject, UInt32 waitForMultipleObjectsTimeout, Boolean allowCreate, Boolean onlyOneCheckConnection, DbConnectionOptions userOptions, DbConnectionInternal& connection)\r\n   at System.Data.ProviderBase.DbConnectionPool.TryGetConnection(DbConnection owningObject, TaskCompletionSource`1 retry, DbConnectionOptions userOptions, DbConnectionInternal& connection)\r\n   at System.Data.ProviderBase.DbConnectionFactory.TryGetConnection(DbConnection owningConnection, TaskCompletionSource`1 retry, DbConnectionOptions userOptions, DbConnectionInternal oldConnection, DbConnectionInternal& connection)\r\n   at System.Data.ProviderBase.DbConnectionInternal.TryOpenConnectionInternal(DbConnection outerConnection, DbConnectionFactory connectionFactory, TaskCompletionSource`1 retry, DbConnectionOptions userOptions)\r\n   at System.Data.SqlClient.SqlConnection.TryOpenInner(TaskCompletionSource`1 retry)\r\n   at System.Data.SqlClient.SqlConnection.TryOpen(TaskCompletionSource`1 retry)\r\n   at System.Data.SqlClient.SqlConnection.Open()\r\n   at NPoco.Database.OpenSharedConnectionImp(Boolean isInternal)\r\n   at NPoco.Database.BeginTransaction(IsolationLevel isolationLevel)\r\n   at Umbraco.Core.Scoping.Scope.get_Database() in D:\\a\\1\\s\\src\\Umbraco.Core\\Scoping\\Scope.cs:line 330\r\n   at Umbraco.Core.Sync.DatabaseServerMessenger.Sync() in D:\\a\\1\\s\\src\\Umbraco.Core\\Sync\\DatabaseServerMessenger.cs:line 263\r\n   at Umbraco.Web.Compose.DatabaseServerRegistrarAndMessengerComponent.InstructionProcessTask.PerformRun() in D:\\a\\1\\s\\src\\Umbraco.Web\\Compose\\DatabaseServerRegistrarAndMessengerComponent.cs:line 163\r\nClientConnectionId:00000000-0000-0000-0000-000000000000\r\nError Number:53,State:0,Class:20","SourceContext":"Umbraco.Web.Compose.DatabaseServerRegistrarAndMessengerComponent+InstructionProcessTask","ProcessId":18916,"ProcessName":"iisexpress","ThreadId":98,"AppDomainId":2,"AppDomainAppId":"LMW3SVC2ROOT","MachineName":"AAR00118","Log4NetLevel":"ERROR"}
{"@t":"2022-02-14T07:44:56.8269321Z","@mt":"Failed (will repeat).","@l":"Error","@x":"System.Data.SqlClient.SqlException (0x80131904): A network-related or instance-specific error occurred while establishing a connection to SQL Server. The server was not found or was not accessible. Verify that the instance name is correct and that SQL Server is configured to allow remote connections. (provider: Named Pipes Provider, error: 40 - Could not open a connection to SQL Server) ---> System.ComponentModel.Win32Exception (0x80004005): The network path was not found\r\n   at System.Data.SqlClient.SqlInternalConnectionTds..ctor(DbConnectionPoolIdentity identity, SqlConnectionString connectionOptions, SqlCredential credential, Object providerInfo, String newPassword, SecureString newSecurePassword, Boolean redirectedUserInstance, SqlConnectionString userConnectionOptions, SessionData reconnectSessionData, DbConnectionPool pool, String accessToken, Boolean applyTransientFaultHandling, SqlAuthenticationProviderManager sqlAuthProviderManager)\r\n   at System.Data.SqlClient.SqlConnectionFactory.CreateConnection(DbConnectionOptions options, DbConnectionPoolKey poolKey, Object poolGroupProviderInfo, DbConnectionPool pool, DbConnection owningConnection, DbConnectionOptions userOptions)\r\n   at System.Data.ProviderBase.DbConnectionFactory.CreatePooledConnection(DbConnectionPool pool, DbConnection owningObject, DbConnectionOptions options, DbConnectionPoolKey poolKey, DbConnectionOptions userOptions)\r\n   at System.Data.ProviderBase.DbConnectionPool.CreateObject(DbConnection owningObject, DbConnectionOptions userOptions, DbConnectionInternal oldConnection)\r\n   at System.Data.ProviderBase.DbConnectionPool.UserCreateRequest(DbConnection owningObject, DbConnectionOptions userOptions, DbConnectionInternal oldConnection)\r\n   at System.Data.ProviderBase.DbConnectionPool.TryGetConnection(DbConnection owningObject, UInt32 waitForMultipleObjectsTimeout, Boolean allowCreate, Boolean onlyOneCheckConnection, DbConnectionOptions userOptions, DbConnectionInternal& connection)\r\n   at System.Data.ProviderBase.DbConnectionPool.TryGetConnection(DbConnection owningObject, TaskCompletionSource`1 retry, DbConnectionOptions userOptions, DbConnectionInternal& connection)\r\n   at System.Data.ProviderBase.DbConnectionFactory.TryGetConnection(DbConnection owningConnection, TaskCompletionSource`1 retry, DbConnectionOptions userOptions, DbConnectionInternal oldConnection, DbConnectionInternal& connection)\r\n   at System.Data.ProviderBase.DbConnectionInternal.TryOpenConnectionInternal(DbConnection outerConnection, DbConnectionFactory connectionFactory, TaskCompletionSource`1 retry, DbConnectionOptions userOptions)\r\n   at System.Data.SqlClient.SqlConnection.TryOpenInner(TaskCompletionSource`1 retry)\r\n   at System.Data.SqlClient.SqlConnection.TryOpen(TaskCompletionSource`1 retry)\r\n   at System.Data.SqlClient.SqlConnection.Open()\r\n   at NPoco.Database.OpenSharedConnectionImp(Boolean isInternal)\r\n   at NPoco.Database.BeginTransaction(IsolationLevel isolationLevel)\r\n   at Umbraco.Core.Scoping.Scope.get_Database() in D:\\a\\1\\s\\src\\Umbraco.Core\\Scoping\\Scope.cs:line 330\r\n   at Umbraco.Core.Sync.DatabaseServerMessenger.Sync() in D:\\a\\1\\s\\src\\Umbraco.Core\\Sync\\DatabaseServerMessenger.cs:line 263\r\n   at Umbraco.Web.Compose.DatabaseServerRegistrarAndMessengerComponent.InstructionProcessTask.PerformRun() in D:\\a\\1\\s\\src\\Umbraco.Web\\Compose\\DatabaseServerRegistrarAndMessengerComponent.cs:line 163\r\nClientConnectionId:00000000-0000-0000-0000-000000000000\r\nError Number:53,State:0,Class:20","SourceContext":"Umbraco.Web.Compose.DatabaseServerRegistrarAndMessengerComponent+InstructionProcessTask","ProcessId":18916,"ProcessName":"iisexpress","ThreadId":96,"AppDomainId":2,"AppDomainAppId":"LMW3SVC2ROOT","MachineName":"AAR00118","Log4NetLevel":"ERROR"}
{"@t":"2022-02-14T07:44:57.5529794Z","@mt":"Failed.","@l":"Error","@x":"System.Data.SqlClient.SqlException (0x80131904): A network-related or instance-specific error occurred while establishing a connection to SQL Server. The server was not found or was not accessible. Verify that the instance name is correct and that SQL Server is configured to allow remote connections. (provider: Named Pipes Provider, error: 40 - Could not open a connection to SQL Server) ---> System.ComponentModel.Win32Exception (0x80004005): The network path was not found\r\n   at System.Data.ProviderBase.DbConnectionPool.TryGetConnection(DbConnection owningObject, UInt32 waitForMultipleObjectsTimeout, Boolean allowCreate, Boolean onlyOneCheckConnection, DbConnectionOptions userOptions, DbConnectionInternal& connection)\r\n   at System.Data.ProviderBase.DbConnectionPool.TryGetConnection(DbConnection owningObject, TaskCompletionSource`1 retry, DbConnectionOptions userOptions, DbConnectionInternal& connection)\r\n   at System.Data.ProviderBase.DbConnectionFactory.TryGetConnection(DbConnection owningConnection, TaskCompletionSource`1 retry, DbConnectionOptions userOptions, DbConnectionInternal oldConnection, DbConnectionInternal& connection)\r\n   at System.Data.ProviderBase.DbConnectionInternal.TryOpenConnectionInternal(DbConnection outerConnection, DbConnectionFactory connectionFactory, TaskCompletionSource`1 retry, DbConnectionOptions userOptions)\r\n   at System.Data.SqlClient.SqlConnection.TryOpenInner(TaskCompletionSource`1 retry)\r\n   at System.Data.SqlClient.SqlConnection.TryOpen(TaskCompletionSource`1 retry)\r\n   at System.Data.SqlClient.SqlConnection.Open()\r\n   at NPoco.Database.OpenSharedConnectionImp(Boolean isInternal)\r\n   at NPoco.Database.BeginTransaction(IsolationLevel isolationLevel)\r\n   at Umbraco.Core.Scoping.Scope.get_Database() in D:\\a\\1\\s\\src\\Umbraco.Core\\Scoping\\Scope.cs:line 330\r\n   at Umbraco.Core.Persistence.Repositories.Implement.DocumentRepository.HasContentForRelease(DateTime date) in D:\\a\\1\\s\\src\\Umbraco.Core\\Persistence\\Repositories\\Implement\\DocumentRepository.cs:line 1050\r\n   at Umbraco.Core.Services.Implement.ContentService.PerformScheduledPublishingRelease(DateTime date, List`1 results, EventMessages evtMsgs, Lazy`1 allLangs) in D:\\a\\1\\s\\src\\Umbraco.Core\\Services\\Implement\\ContentService.cs:line 1467\r\n   at Umbraco.Core.Services.Implement.ContentService.PerformScheduledPublish(DateTime date) in D:\\a\\1\\s\\src\\Umbraco.Core\\Services\\Implement\\ContentService.cs:line 1396\r\n   at Umbraco.Web.Scheduling.ScheduledPublishing.PerformRun() in D:\\a\\1\\s\\src\\Umbraco.Web\\Scheduling\\ScheduledPublishing.cs:line 68\r\nClientConnectionId:00000000-0000-0000-0000-000000000000\r\nError Number:53,State:0,Class:20","SourceContext":"Umbraco.Web.Scheduling.ScheduledPublishing","ProcessId":18916,"ProcessName":"iisexpress","ThreadId":92,"AppDomainId":2,"AppDomainAppId":"LMW3SVC2ROOT","MachineName":"AAR00118","Log4NetLevel":"ERROR"}
{"@t":"2022-02-14T07:45:01.8390874Z","@mt":"Failed (will repeat).","@l":"Error","@x":"System.Data.SqlClient.SqlException (0x80131904): A network-related or instance-specific error occurred while establishing a connection to SQL Server. The server was not found or was not accessible. Verify that the instance name is correct and that SQL Server is configured to allow remote connections. (provider: Named Pipes Provider, error: 40 - Could not open a connection to SQL Server) ---> System.ComponentModel.Win32Exception (0x80004005): The network path was not found\r\n   at System.Data.ProviderBase.DbConnectionPool.TryGetConnection(DbConnection owningObject, UInt32 waitForMultipleObjectsTimeout, Boolean allowCreate, Boolean onlyOneCheckConnection, DbConnectionOptions userOptions, DbConnectionInternal& connection)\r\n   at System.Data.ProviderBase.DbConnectionPool.TryGetConnection(DbConnection owningObject, TaskCompletionSource`1 retry, DbConnectionOptions userOptions, DbConnectionInternal& connection)\r\n   at System.Data.ProviderBase.DbConnectionFactory.TryGetConnection(DbConnection owningConnection, TaskCompletionSource`1 retry, DbConnectionOptions userOptions, DbConnectionInternal oldConnection, DbConnectionInternal& connection)\r\n   at System.Data.ProviderBase.DbConnectionInternal.TryOpenConnectionInternal(DbConnection outerConnection, DbConnectionFactory connectionFactory, TaskCompletionSource`1 retry, DbConnectionOptions userOptions)\r\n   at System.Data.SqlClient.SqlConnection.TryOpenInner(TaskCompletionSource`1 retry)\r\n   at System.Data.SqlClient.SqlConnection.TryOpen(TaskCompletionSource`1 retry)\r\n   at System.Data.SqlClient.SqlConnection.Open()\r\n   at NPoco.Database.OpenSharedConnectionImp(Boolean isInternal)\r\n   at NPoco.Database.BeginTransaction(IsolationLevel isolationLevel)\r\n   at Umbraco.Core.Scoping.Scope.get_Database() in D:\\a\\1\\s\\src\\Umbraco.Core\\Scoping\\Scope.cs:line 330\r\n   at Umbraco.Core.Sync.DatabaseServerMessenger.Sync() in D:\\a\\1\\s\\src\\Umbraco.Core\\Sync\\DatabaseServerMessenger.cs:line 263\r\n   at Umbraco.Web.Compose.DatabaseServerRegistrarAndMessengerComponent.InstructionProcessTask.PerformRun() in D:\\a\\1\\s\\src\\Umbraco.Web\\Compose\\DatabaseServerRegistrarAndMessengerComponent.cs:line 163\r\nClientConnectionId:00000000-0000-0000-0000-000000000000\r\nError Number:53,State:0,Class:20","SourceContext":"Umbraco.Web.Compose.DatabaseServerRegistrarAndMessengerComponent+InstructionProcessTask","ProcessId":18916,"ProcessName":"iisexpress","ThreadId":96,"AppDomainId":2,"AppDomainAppId":"LMW3SVC2ROOT","MachineName":"AAR00118","Log4NetLevel":"ERROR"}
{"@t":"2022-02-14T07:45:06.8804692Z","@mt":"Failed (will repeat).","@l":"Error","@x":"System.Data.SqlClient.SqlException (0x80131904): A network-related or instance-specific error occurred while establishing a connection to SQL Server. The server was not found or was not accessible. Verify that the instance name is correct and that SQL Server is configured to allow remote connections. (provider: Named Pipes Provider, error: 40 - Could not open a connection to SQL Server) ---> System.ComponentModel.Win32Exception (0x80004005): The network path was not found\r\n   at System.Data.ProviderBase.DbConnectionPool.TryGetConnection(DbConnection owningObject, UInt32 waitForMultipleObjectsTimeout, Boolean allowCreate, Boolean onlyOneCheckConnection, DbConnectionOptions userOptions, DbConnectionInternal& connection)\r\n   at System.Data.ProviderBase.DbConnectionPool.TryGetConnection(DbConnection owningObject, TaskCompletionSource`1 retry, DbConnectionOptions userOptions, DbConnectionInternal& connection)\r\n   at System.Data.ProviderBase.DbConnectionFactory.TryGetConnection(DbConnection owningConnection, TaskCompletionSource`1 retry, DbConnectionOptions userOptions, DbConnectionInternal oldConnection, DbConnectionInternal& connection)\r\n   at System.Data.ProviderBase.DbConnectionInternal.TryOpenConnectionInternal(DbConnection outerConnection, DbConnectionFactory connectionFactory, TaskCompletionSource`1 retry, DbConnectionOptions userOptions)\r\n   at System.Data.SqlClient.SqlConnection.TryOpenInner(TaskCompletionSource`1 retry)\r\n   at System.Data.SqlClient.SqlConnection.TryOpen(TaskCompletionSource`1 retry)\r\n   at System.Data.SqlClient.SqlConnection.Open()\r\n   at NPoco.Database.OpenSharedConnectionImp(Boolean isInternal)\r\n   at NPoco.Database.BeginTransaction(IsolationLevel isolationLevel)\r\n   at Umbraco.Core.Scoping.Scope.get_Database() in D:\\a\\1\\s\\src\\Umbraco.Core\\Scoping\\Scope.cs:line 330\r\n   at Umbraco.Core.Sync.DatabaseServerMessenger.Sync() in D:\\a\\1\\s\\src\\Umbraco.Core\\Sync\\DatabaseServerMessenger.cs:line 263\r\n   at Umbraco.Web.Compose.DatabaseServerRegistrarAndMessengerComponent.InstructionProcessTask.PerformRun() in D:\\a\\1\\s\\src\\Umbraco.Web\\Compose\\DatabaseServerRegistrarAndMessengerComponent.cs:line 163\r\nClientConnectionId:00000000-0000-0000-0000-000000000000\r\nError Number:53,State:0,Class:20","SourceContext":"Umbraco.Web.Compose.DatabaseServerRegistrarAndMessengerComponent+InstructionProcessTask","ProcessId":18916,"ProcessName":"iisexpress","ThreadId":64,"AppDomainId":2,"AppDomainAppId":"LMW3SVC2ROOT","MachineName":"AAR00118","Log4NetLevel":"ERROR"}
{"@t":"2022-02-14T07:45:11.8961060Z","@mt":"Failed (will repeat).","@l":"Error","@x":"System.Data.SqlClient.SqlException (0x80131904): A network-related or instance-specific error occurred while establishing a connection to SQL Server. The server was not found or was not accessible. Verify that the instance name is correct and that SQL Server is configured to allow remote connections. (provider: Named Pipes Provider, error: 40 - Could not open a connection to SQL Server) ---> System.ComponentModel.Win32Exception (0x80004005): The network path was not found\r\n   at System.Data.ProviderBase.DbConnectionPool.TryGetConnection(DbConnection owningObject, UInt32 waitForMultipleObjectsTimeout, Boolean allowCreate, Boolean onlyOneCheckConnection, DbConnectionOptions userOptions, DbConnectionInternal& connection)\r\n   at System.Data.ProviderBase.DbConnectionPool.TryGetConnection(DbConnection owningObject, TaskCompletionSource`1 retry, DbConnectionOptions userOptions, DbConnectionInternal& connection)\r\n   at System.Data.ProviderBase.DbConnectionFactory.TryGetConnection(DbConnection owningConnection, TaskCompletionSource`1 retry, DbConnectionOptions userOptions, DbConnectionInternal oldConnection, DbConnectionInternal& connection)\r\n   at System.Data.ProviderBase.DbConnectionInternal.TryOpenConnectionInternal(DbConnection outerConnection, DbConnectionFactory connectionFactory, TaskCompletionSource`1 retry, DbConnectionOptions userOptions)\r\n   at System.Data.SqlClient.SqlConnection.TryOpenInner(TaskCompletionSource`1 retry)\r\n   at System.Data.SqlClient.SqlConnection.TryOpen(TaskCompletionSource`1 retry)\r\n   at System.Data.SqlClient.SqlConnection.Open()\r\n   at NPoco.Database.OpenSharedConnectionImp(Boolean isInternal)\r\n   at NPoco.Database.BeginTransaction(IsolationLevel isolationLevel)\r\n   at Umbraco.Core.Scoping.Scope.get_Database() in D:\\a\\1\\s\\src\\Umbraco.Core\\Scoping\\Scope.cs:line 330\r\n   at Umbraco.Core.Sync.DatabaseServerMessenger.Sync() in D:\\a\\1\\s\\src\\Umbraco.Core\\Sync\\DatabaseServerMessenger.cs:line 263\r\n   at Umbraco.Web.Compose.DatabaseServerRegistrarAndMessengerComponent.InstructionProcessTask.PerformRun() in D:\\a\\1\\s\\src\\Umbraco.Web\\Compose\\DatabaseServerRegistrarAndMessengerComponent.cs:line 163\r\nClientConnectionId:00000000-0000-0000-0000-000000000000\r\nError Number:53,State:0,Class:20","SourceContext":"Umbraco.Web.Compose.DatabaseServerRegistrarAndMessengerComponent+InstructionProcessTask","ProcessId":18916,"ProcessName":"iisexpress","ThreadId":89,"AppDomainId":2,"AppDomainAppId":"LMW3SVC2ROOT","MachineName":"AAR00118","Log4NetLevel":"ERROR"}
{"@t":"2022-02-14T07:51:28.4141717Z","@mt":"[{EventType}] Event Id: {EventId}, State: {State}","EventType":"Information","EventId":0,"State":"Login attempt succeeded for username oliver.gjesing@akqa.com from IP address ::1","SourceContext":"Umbraco.Core.Logging.OwinLogger","ProcessId":18916,"ProcessName":"iisexpress","ThreadId":99,"AppDomainId":2,"AppDomainAppId":"LMW3SVC2ROOT","MachineName":"AAR00118","Log4NetLevel":"INFO ","HttpRequestNumber":7,"HttpRequestId":"0ecc432e-2935-4895-80f4-d9d9ba3ba77f"}
{"@t":"2022-02-14T07:51:28.4141717Z","@mt":"[{EventType}] Event Id: {EventId}, State: {State}","EventType":"Information","EventId":0,"State":"User: oliver.gjesing@akqa.com logged in from IP address ::1","SourceContext":"Umbraco.Core.Logging.OwinLogger","ProcessId":18916,"ProcessName":"iisexpress","ThreadId":99,"AppDomainId":2,"AppDomainAppId":"LMW3SVC2ROOT","MachineName":"AAR00118","Log4NetLevel":"INFO ","HttpRequestNumber":7,"HttpRequestId":"0ecc432e-2935-4895-80f4-d9d9ba3ba77f"}
{"@t":"2022-02-14T07:51:40.7786321Z","@mt":"Exception","@l":"Error","@x":"ImageProcessor.Common.Exceptions.ImageProcessingException: ProcessImageAsync 609 : No image exists at D:\\Users\\Oliver.Gjesing.EMEA\\Documents\\Git\\FTO\\BE\\Flight2Orbit\\media\\bddkxw1w\\9368855062_a548b9c5eb_o.jpg","SourceContext":"ImageProcessor.Web.HttpModules.ImageProcessingModule","ProcessId":18916,"ProcessName":"iisexpress","ThreadId":110,"AppDomainId":2,"AppDomainAppId":"LMW3SVC2ROOT","MachineName":"AAR00118","Log4NetLevel":"ERROR","HttpRequestNumber":8,"HttpRequestId":"deacae7f-9bfc-4e4e-b9e5-ca73ab727f94"}
